Workbook
Name daftarnama: siswa!$C$2:$C$39

Sheet petunjuk
A1: instruksi
A2: Isi baris yang disediakan. SPP bulan depan dibuat otomatis. Tunggakan SPP lama dicatat di sheet tagihan dengan jenis_tagihan = spp dan bulan_tahun diisi. Kolom jenis_tagihan wajib sama dengan di sistem.

Sheet siswa
A1: kode_import_siswa | B1: nis | C1: nama_siswa | D1: tanggal_lahir | E1: jenis_kelamin | F1: nama_wali | G1: kontak_wali | H1: alamat | I1: status | J1: jenis_masuk | K1: tanggal_daftar | L1: tingkat | M1: kelas | N1: tanggal_keluar | O1: alasan_keluar | P1: tarif_spp_khusus | Q1: alasan_tarif_spp_khusus | R1: nama_promo
A2: S001 | B2: 2526001 | C2: Abhimanyu Kenzo Novendra | D2: 44139 | E2: L | F2: Fery Juanda | G2: 081234567890 | H2: GIS BLOK K4/5 | I2: aktif | J2: awal_tahun | K2: 45839 | L2: TK A | M2: TK A
A3: S002 | B3: 2526002 | C3: Adzriel Al Mahdi | D3: 43867 | E3: L | F3: Umar Hari Setyawan | H3: GIS BLOK L5/10 | I3: aktif | J3: awal_tahun | K3: 45840 | L3: TK B | M3: TK B
A4: S003 | B4: 2526003 | C4: Afifa Aina Herita | D4: 43649 | E4: P | F4: Heru Susanto | H4: GIS BLOK R | I4: aktif | J4: awal_tahun | K4: 45841 | L4: TK B | M4: TK B
A5: S004 | B5: 2526004 | C5: Aiza Nuha Mafaza | D5: 44014 | E5: P | F5: Rahmad Hidayat | H5: GIS BLOK H2/10 | I5: aktif | J5: awal_tahun | K5: 45839 | L5: TK A | M5: TK A
A6: S005 | B6: 2526005 | C6: Aleena Savrinadeya | D6: 44356 | E6: P | F6: Muhamad Sofi | H6: GIS BLOK D2/16 | I6: keluar | J6: awal_tahun | K6: 45839 | L6: KB | M6: KB | N6: 45870 | O6: berhenti_lainnya
A7: S006 | B7: 2526006 | C7: Aqmar Nadhif Ramdhan | D7: 43886 | E7: L | F7: Sahrulloh | H7: CBR BLOK B8/16 | I7: aktif | J7: awal_tahun | K7: 45839 | L7: TK B | M7: TK B | P7: 220000
A8: S007 | B8: 2526007 | C8: Asiyah Noora Amanda | D8: 44762 | E8: P | F8: Ermanda Saputra | H8: Rumah SB kel. GIS | I8: aktif | J8: awal_tahun | K8: 45839 | L8: KB | M8: KB
A9: S008 | B9: 2526008 | C9: Dhen Adipati Siliwangi | D9: 43651 | E9: L | F9: Suratman | H9: GIS BLOK L4/7 | I9: keluar | J9: awal_tahun | K9: 45839 | L9: TK B | M9: TK B | N9: 46017 | O9: pindah_sekolah
A10: S009 | B10: 2526009 | C10: Elma Hazel Maulida | D10: 43779 | E10: P | F10: Endin Diana Saputra | H10: GIS BLOK R5/6 | I10: aktif | J10: awal_tahun | K10: 45839 | L10: TK B | M10: TK B
A11: S010 | B11: 23240020 | C11: Farhana Athabina | D11: 44069 | E11: P | F11: M. Ardiansyah | H11: GIS BLOK G2/9 | I11: aktif | J11: awal_tahun | K11: 45839 | L11: TK A | M11: TK A
A12: S011 | B12: 24250003 | C12: Fawwaz Khayri Zain | D12: 44018 | E12: L | F12: Dany Ilyansyah | H12: GIS BLOK L6/11 | I12: aktif | J12: awal_tahun | K12: 45839 | L12: TK B | M12: TK B | P12: 220000
A13: S012 | B13: 2526010 | C13: Gita Nuraisya Gunawan | D13: 43588 | E13: P | F13: Dodi Gunawan | H13: GIS BLOK M1/16 | I13: aktif | J13: awal_tahun | K13: 45839 | L13: TK B | M13: TK B
A14: S013 | B14: 2526011 | C14: Hanindhiya Izza Susanto | D14: 44086 | E14: P | F14: Heri Susanto | H14: GIS BLOK G7/6 | I14: aktif | J14: awal_tahun | K14: 45839 | L14: TK A | M14: TK A
A15: S014 | B15: 2526012 | C15: Keanu Osama Al Jabbar | D15: 43655 | E15: L | F15: Saibudin Soleh | H15: GIS BLOK Q6/23 | I15: aktif | J15: awal_tahun | K15: 45839 | L15: TK B | M15: TK B
A16: S015 | B16: 2526013 | C16: Kenzie Fabbiyan Armana Sipayung | D16: 44246 | E16: L | F16: Ihwan Arifudin | H16: GIS BLOK N9/3 | I16: aktif | J16: awal_tahun | K16: 45839 | L16: TK A | M16: TK A
A17: S016 | B17: 2526014 | C17: Khawla Nizia Anwar | D17: 44172 | E17: P | F17: Wagiman | H17: GIS BLOK B2/18 | I17: aktif | J17: awal_tahun | K17: 45839 | L17: TK A | M17: TK A | P17: 220000
A18: S017 | B18: 2526015 | C18: M. Azka Putra Ananta | D18: 44311 | E18: L | F18: L. Ananta Sigit Sidharta | H18: GIS BLOK U2/8 | I18: aktif | J18: awal_tahun | K18: 45839 | L18: TK A | M18: TK A
A19: S018 | B19: 2526016 | C19: M. Azki Putra Ananta | D19: 44311 | E19: L | F19: L. Ananta Sigit Sidharta | H19: GIS BLOK U2/8 | I19: aktif | J19: awal_tahun | K19: 45839 | L19: TK A | M19: TK A
A20: S019 | B20: 2526017 | C20: M. Dhaffin Al Haqqi | D20: 43740 | E20: L | F20: Asep Agus Salim | H20: GIS BLOK P3/5 | I20: aktif | J20: awal_tahun | K20: 45839 | L20: TK B | M20: TK B
A21: S020 | B21: 24250006 | C21: M. Nazhif Alfarizqi | D21: 43567 | E21: L | F21: Muhammad Zen | H21: GIS BLOK L2/10 | I21: aktif | J21: awal_tahun | K21: 45839 | L21: TK B | M21: TK B | P21: 200000
A22: S021 | B22: 2526018 | C22: Mainaka Syailendra Firmansyah | D22: 44177 | E22: L | F22: Meidi Firmansyah | H22: Kp. Cibinong RT 3/5 | I22: aktif | J22: awal_tahun | K22: 45839 | L22: TK A | M22: TK A
A23: S022 | B23: 2526019 | C23: Muhammad Al Farizzi | D23: 43738 | E23: L | F23: Ricky Rosadi | H23: GIS BLOK L5/23 | I23: aktif | J23: awal_tahun | K23: 45839 | L23: TK B | M23: TK B
A24: S023 | B24: 2526021 | C24: Muhammad Zafran Aditya | D24: 43840 | E24: L | F24: Dhimas Aditya | H24: GIS BLOK A5/20 | I24: keluar | J24: awal_tahun | K24: 45839 | L24: TK B | M24: TK B | N24: 46028 | O24: pindah_sekolah
A25: S024 | B25: 2526022 | C25: Nakula Putra Obhay | D25: 44153 | E25: L | F25: Muhammad | H25: GIS BLOK R10/16 | I25: aktif | J25: awal_tahun | K25: 45839 | L25: TK A | M25: TK A
A26: S025 | B26: 2526023 | C26: Naufal Al Fauzan | D26: 43710 | E26: L | F26: Niko Rosadi | H26: GIS BLOK L5/18 | I26: aktif | J26: awal_tahun | K26: 45839 | L26: TK B | M26: TK B
A27: S026 | B27: 2526024 | C27: Naura Aini Ramadhani | D27: 43967 | E27: P | F27: Sutrisno | H27: GIS BLOK Q2/1 | I27: aktif | J27: awal_tahun | K27: 45839 | L27: TK B | M27: TK B
A28: S027 | B28: 2526025 | C28: Nicholas Al Farizi | D28: 43356 | E28: L | F28: Dwi Bassri | H28: GIS BLOK H2/16 | I28: keluar | J28: awal_tahun | K28: 45839 | L28: TK B | M28: TK B | N28: 45965 | O28: pindah_sekolah
A29: S028 | B29: 23240021 | C29: R. M. Alfarizi Aidil Muntoro | D29: 43681 | E29: L | F29: Sari Muntoro | H29: GIS BLOK I7/10 | I29: aktif | J29: awal_tahun | K29: 45839 | L29: TK B | M29: TK B | P29: 150000
A30: S029 | B30: 2526026 | C30: Rafif Fatir Andriansyah | D30: 44797 | E30: L | F30: Azmi Firli Andriansyah | H30: GIS BLOK N2/5 | I30: aktif | J30: awal_tahun | K30: 45839 | L30: KB | M30: KB
A31: S030 | B31: 2526027 | C31: Raga Azki Setyawan | D31: 44917 | E31: L | F31: Rangga Setyawan | H31: Kp. Glusur RT 1/9/66 | I31: aktif | J31: awal_tahun | K31: 45839 | L31: KB | M31: KB
A32: S031 | B32: 2526029 | C32: Raissa Salsabila Aisy | D32: 43804 | E32: P | F32: Umarudin | H32: GIS BLOK G2/7 | I32: aktif | J32: awal_tahun | K32: 45839 | L32: TK B | M32: TK B
A33: S032 | B33: 24250006 | C33: Rasyid Al Fakhri Rohim | D33: 43823 | E33: L | F33: Fahmi | H33: GIS N5/11 | I33: aktif | J33: awal_tahun | K33: 45839 | L33: TK B | M33: TK B
A34: S033 | B34: 2526030 | C34: Sadewa Putra Obhay | D34: 44153 | E34: L | F34: Muhammad | H34: GIS BLOK R10/16 | I34: aktif | J34: awal_tahun | K34: 45839 | L34: TK A | M34: TK A
A35: S034 | B35: 2526031 | C35: Shanum Eishal Aisyah | D35: 44123 | E35: P | F35: Hartanto | H35: GIS BLOK K20/3 | I35: aktif | J35: awal_tahun | K35: 45839 | L35: TK A | M35: TK A
A36: S035 | B36: 2526020 | C36: Muhammad Syabil Al Farizky | D36: 44741 | E36: L | F36: Ade Kurniahu | H36: GIS BLOK Q4/29 | I36: aktif | J36: pindahan | K36: 45689 | L36: KB | M36: KB
A37: S036 | B37: 2526032 | C37: Tsania Fitri Zulkifli | D37: 43986 | E37: P | F37: Ridwanullah Mua'fa | H37: GIS BLOK B1/11 | I37: aktif | J37: pindahan | K37: 45839 | L37: TK A | M37: TK A
A38: S037 | C38: Aisyah Humaira | D38: 43832 | E38: P | F38: Chandra | H38: Kp. Cogreg RT 02/02 | I38: aktif | J38: pindahan | K38: 46082 | L38: TK B | M38: TK B
A39: S038 | C39: Raja Azki Setyawan | D39: 43863 | E39: L | F39: Rangga Setyawan | H39: Kp. Glusur RT 1/9/66 | I39: aktif | J39: pindahan | K39: 46113 | L39: TK B | M39: TK B

Sheet tagihan
A1: kode_import_tagihan | B1: kode_import_siswa | C1: jenis_tagihan | D1: bulan_tahun | E1: nama_tagihan | F1: jumlah_total | G1: nama_promo | H1: nominal_diskon | I1: jatuh_tempo | J1: bisa_cicil
A2: T001 | B2: S001 | C2: spp | D2: =IF(ISNUMBER(SEARCH("Juli",E2)),"2025-07", IF(ISNUMBER(SEARCH("Agustus",E2)),"2025-08", IF(ISNUMBER(SEARCH("September",E2)),"2025-09", IF(ISNUMBER(SEARCH("Oktober",E2)),"2025-10", IF(ISNUMBER(SEARCH("November",E2)),"2025-11", IF(ISNUMBER(SEARCH("Desember",E2)),"2025-12", IF(ISNUMBER(SEARCH("Januari",E2)),"2026-01", IF(ISNUMBER(SEARCH("Februari",E2)),"2026-02", IF(ISNUMBER(SEARCH("Maret",E2)),"2026-03", IF(ISNUMBER(SEARCH("April",E2)),"2026-04", IF(ISNUMBER(SEARCH("Mei",E2)),"2026-05", IF(ISNUMBER(SEARCH("Juni",E2)),"2026-06","")))))))))))) -> 2025-07 | E2: SPP Juli | F2: 230000 | G2: pendaftaran | H2: =IF(ISNUMBER(SEARCH("Juli",E2)),230000,"") -> 230000 | I2: =DATE(LEFT(D2,4),RIGHT(D2,2),10) -> 45848
A3: T002 | B3: S001 | C3: spp | D3: =IF(ISNUMBER(SEARCH("Juli",E3)),"2025-07", IF(ISNUMBER(SEARCH("Agustus",E3)),"2025-08", IF(ISNUMBER(SEARCH("September",E3)),"2025-09", IF(ISNUMBER(SEARCH("Oktober",E3)),"2025-10", IF(ISNUMBER(SEARCH("November",E3)),"2025-11", IF(ISNUMBER(SEARCH("Desember",E3)),"2025-12", IF(ISNUMBER(SEARCH("Januari",E3)),"2026-01", IF(ISNUMBER(SEARCH("Februari",E3)),"2026-02", IF(ISNUMBER(SEARCH("Maret",E3)),"2026-03", IF(ISNUMBER(SEARCH("April",E3)),"2026-04", IF(ISNUMBER(SEARCH("Mei",E3)),"2026-05", IF(ISNUMBER(SEARCH("Juni",E3)),"2026-06","")))))))))))) -> 2025-08 | E3: SPP Agustus | F3: 230000 | H3: =IF(ISNUMBER(SEARCH("Juli",E3)),230000,"") | I3: =DATE(LEFT(D3,4),RIGHT(D3,2),10) -> 45879
A4: T003 | B4: S001 | C4: spp | D4: =IF(ISNUMBER(SEARCH("Juli",E4)),"2025-07", IF(ISNUMBER(SEARCH("Agustus",E4)),"2025-08", IF(ISNUMBER(SEARCH("September",E4)),"2025-09", IF(ISNUMBER(SEARCH("Oktober",E4)),"2025-10", IF(ISNUMBER(SEARCH("November",E4)),"2025-11", IF(ISNUMBER(SEARCH("Desember",E4)),"2025-12", IF(ISNUMBER(SEARCH("Januari",E4)),"2026-01", IF(ISNUMBER(SEARCH("Februari",E4)),"2026-02", IF(ISNUMBER(SEARCH("Maret",E4)),"2026-03", IF(ISNUMBER(SEARCH("April",E4)),"2026-04", IF(ISNUMBER(SEARCH("Mei",E4)),"2026-05", IF(ISNUMBER(SEARCH("Juni",E4)),"2026-06","")))))))))))) -> 2025-09 | E4: SPP September | F4: 230000 | H4: =IF(ISNUMBER(SEARCH("Juli",E4)),230000,"") | I4: =DATE(LEFT(D4,4),RIGHT(D4,2),10) -> 45910
A5: T004 | B5: S001 | C5: spp | D5: =IF(ISNUMBER(SEARCH("Juli",E5)),"2025-07", IF(ISNUMBER(SEARCH("Agustus",E5)),"2025-08", IF(ISNUMBER(SEARCH("September",E5)),"2025-09", IF(ISNUMBER(SEARCH("Oktober",E5)),"2025-10", IF(ISNUMBER(SEARCH("November",E5)),"2025-11", IF(ISNUMBER(SEARCH("Desember",E5)),"2025-12", IF(ISNUMBER(SEARCH("Januari",E5)),"2026-01", IF(ISNUMBER(SEARCH("Februari",E5)),"2026-02", IF(ISNUMBER(SEARCH("Maret",E5)),"2026-03", IF(ISNUMBER(SEARCH("April",E5)),"2026-04", IF(ISNUMBER(SEARCH("Mei",E5)),"2026-05", IF(ISNUMBER(SEARCH("Juni",E5)),"2026-06","")))))))))))) -> 2025-10 | E5: SPP Oktober | F5: 230000 | H5: =IF(ISNUMBER(SEARCH("Juli",E5)),230000,"") | I5: =DATE(LEFT(D5,4),RIGHT(D5,2),10) -> 45940
A6: T005 | B6: S001 | C6: spp | D6: =IF(ISNUMBER(SEARCH("Juli",E6)),"2025-07", IF(ISNUMBER(SEARCH("Agustus",E6)),"2025-08", IF(ISNUMBER(SEARCH("September",E6)),"2025-09", IF(ISNUMBER(SEARCH("Oktober",E6)),"2025-10", IF(ISNUMBER(SEARCH("November",E6)),"2025-11", IF(ISNUMBER(SEARCH("Desember",E6)),"2025-12", IF(ISNUMBER(SEARCH("Januari",E6)),"2026-01", IF(ISNUMBER(SEARCH("Februari",E6)),"2026-02", IF(ISNUMBER(SEARCH("Maret",E6)),"2026-03", IF(ISNUMBER(SEARCH("April",E6)),"2026-04", IF(ISNUMBER(SEARCH("Mei",E6)),"2026-05", IF(ISNUMBER(SEARCH("Juni",E6)),"2026-06","")))))))))))) -> 2025-11 | E6: SPP November | F6: 230000 | H6: =IF(ISNUMBER(SEARCH("Juli",E6)),230000,"") | I6: =DATE(LEFT(D6,4),RIGHT(D6,2),10) -> 45971
A7: T006 | B7: S001 | C7: spp | D7: =IF(ISNUMBER(SEARCH("Juli",E7)),"2025-07", IF(ISNUMBER(SEARCH("Agustus",E7)),"2025-08", IF(ISNUMBER(SEARCH("September",E7)),"2025-09", IF(ISNUMBER(SEARCH("Oktober",E7)),"2025-10", IF(ISNUMBER(SEARCH("November",E7)),"2025-11", IF(ISNUMBER(SEARCH("Desember",E7)),"2025-12", IF(ISNUMBER(SEARCH("Januari",E7)),"2026-01", IF(ISNUMBER(SEARCH("Februari",E7)),"2026-02", IF(ISNUMBER(SEARCH("Maret",E7)),"2026-03", IF(ISNUMBER(SEARCH("April",E7)),"2026-04", IF(ISNUMBER(SEARCH("Mei",E7)),"2026-05", IF(ISNUMBER(SEARCH("Juni",E7)),"2026-06","")))))))))))) -> 2025-12 | E7: SPP Desember | F7: 230000 | H7: =IF(ISNUMBER(SEARCH("Juli",E7)),230000,"") | I7: =DATE(LEFT(D7,4),RIGHT(D7,2),10) -> 46001
A8: T007 | B8: S001 | C8: spp | D8: =IF(ISNUMBER(SEARCH("Juli",E8)),"2025-07", IF(ISNUMBER(SEARCH("Agustus",E8)),"2025-08", IF(ISNUMBER(SEARCH("September",E8)),"2025-09", IF(ISNUMBER(SEARCH("Oktober",E8)),"2025-10", IF(ISNUMBER(SEARCH("November",E8)),"2025-11", IF(ISNUMBER(SEARCH("Desember",E8)),"2025-12", IF(ISNUMBER(SEARCH("Januari",E8)),"2026-01", IF(ISNUMBER(SEARCH("Februari",E8)),"2026-02", IF(ISNUMBER(SEARCH("Maret",E8)),"2026-03", IF(ISNUMBER(SEARCH("April",E8)),"2026-04", IF(ISNUMBER(SEARCH("Mei",E8)),"2026-05", IF(ISNUMBER(SEARCH("Juni",E8)),"2026-06","")))))))))))) -> 2026-01 | E8: SPP Januari | F8: 230000 | H8: =IF(ISNUMBER(SEARCH("Juli",E8)),230000,"") | I8: =DATE(LEFT(D8,4),RIGHT(D8,2),10) -> 46032
A9: T008 | B9: S001 | C9: spp | D9: =IF(ISNUMBER(SEARCH("Juli",E9)),"2025-07", IF(ISNUMBER(SEARCH("Agustus",E9)),"2025-08", IF(ISNUMBER(SEARCH("September",E9)),"2025-09", IF(ISNUMBER(SEARCH("Oktober",E9)),"2025-10", IF(ISNUMBER(SEARCH("November",E9)),"2025-11", IF(ISNUMBER(SEARCH("Desember",E9)),"2025-12", IF(ISNUMBER(SEARCH("Januari",E9)),"2026-01", IF(ISNUMBER(SEARCH("Februari",E9)),"2026-02", IF(ISNUMBER(SEARCH("Maret",E9)),"2026-03", IF(ISNUMBER(SEARCH("April",E9)),"2026-04", IF(ISNUMBER(SEARCH("Mei",E9)),"2026-05", IF(ISNUMBER(SEARCH("Juni",E9)),"2026-06","")))))))))))) -> 2026-02 | E9: SPP Februari | F9: 230000 | H9: =IF(ISNUMBER(SEARCH("Juli",E9)),230000,"") | I9: =DATE(LEFT(D9,4),RIGHT(D9,2),10) -> 46063
A10: T009 | B10: S001 | C10: spp | D10: =IF(ISNUMBER(SEARCH("Juli",E10)),"2025-07", IF(ISNUMBER(SEARCH("Agustus",E10)),"2025-08", IF(ISNUMBER(SEARCH("September",E10)),"2025-09", IF(ISNUMBER(SEARCH("Oktober",E10)),"2025-10", IF(ISNUMBER(SEARCH("November",E10)),"2025-11", IF(ISNUMBER(SEARCH("Desember",E10)),"2025-12", IF(ISNUMBER(SEARCH("Januari",E10)),"2026-01", IF(ISNUMBER(SEARCH("Februari",E10)),"2026-02", IF(ISNUMBER(SEARCH("Maret",E10)),"2026-03", IF(ISNUMBER(SEARCH("April",E10)),"2026-04", IF(ISNUMBER(SEARCH("Mei",E10)),"2026-05", IF(ISNUMBER(SEARCH("Juni",E10)),"2026-06","")))))))))))) -> 2026-03 | E10: SPP Maret | F10: 230000 | H10: =IF(ISNUMBER(SEARCH("Juli",E10)),230000,"") | I10: =DATE(LEFT(D10,4),RIGHT(D10,2),10) -> 46091
A11: T010 | B11: S001 | C11: spp | D11: =IF(ISNUMBER(SEARCH("Juli",E11)),"2025-07", IF(ISNUMBER(SEARCH("Agustus",E11)),"2025-08", IF(ISNUMBER(SEARCH("September",E11)),"2025-09", IF(ISNUMBER(SEARCH("Oktober",E11)),"2025-10", IF(ISNUMBER(SEARCH("November",E11)),"2025-11", IF(ISNUMBER(SEARCH("Desember",E11)),"2025-12", IF(ISNUMBER(SEARCH("Januari",E11)),"2026-01", IF(ISNUMBER(SEARCH("Februari",E11)),"2026-02", IF(ISNUMBER(SEARCH("Maret",E11)),"2026-03", IF(ISNUMBER(SEARCH("April",E11)),"2026-04", IF(ISNUMBER(SEARCH("Mei",E11)),"2026-05", IF(ISNUMBER(SEARCH("Juni",E11)),"2026-06","")))))))))))) -> 2026-04 | E11: SPP April | F11: 230000 | H11: =IF(ISNUMBER(SEARCH("Juli",E11)),230000,"") | I11: =DATE(LEFT(D11,4),RIGHT(D11,2),10) -> 46122
A12: T011 | B12: S002 | C12: spp | D12: =IF(ISNUMBER(SEARCH("Juli",E12)),"2025-07", IF(ISNUMBER(SEARCH("Agustus",E12)),"2025-08", IF(ISNUMBER(SEARCH("September",E12)),"2025-09", IF(ISNUMBER(SEARCH("Oktober",E12)),"2025-10", IF(ISNUMBER(SEARCH("November",E12)),"2025-11", IF(ISNUMBER(SEARCH("Desember",E12)),"2025-12", IF(ISNUMBER(SEARCH("Januari",E12)),"2026-01", IF(ISNUMBER(SEARCH("Februari",E12)),"2026-02", IF(ISNUMBER(SEARCH("Maret",E12)),"2026-03", IF(ISNUMBER(SEARCH("April",E12)),"2026-04", IF(ISNUMBER(SEARCH("Mei",E12)),"2026-05", IF(ISNUMBER(SEARCH("Juni",E12)),"2026-06","")))))))))))) -> 2025-07 | E12: SPP Juli | F12: 230000 | G12: pendaftaran | H12: =IF(ISNUMBER(SEARCH("Juli",E12)),230000,"") -> 230000 | I12: =DATE(LEFT(D12,4),RIGHT(D12,2),10) -> 45848
A13: T012 | B13: S002 | C13: spp | D13: =IF(ISNUMBER(SEARCH("Juli",E13)),"2025-07", IF(ISNUMBER(SEARCH("Agustus",E13)),"2025-08", IF(ISNUMBER(SEARCH("September",E13)),"2025-09", IF(ISNUMBER(SEARCH("Oktober",E13)),"2025-10", IF(ISNUMBER(SEARCH("November",E13)),"2025-11", IF(ISNUMBER(SEARCH("Desember",E13)),"2025-12", IF(ISNUMBER(SEARCH("Januari",E13)),"2026-01", IF(ISNUMBER(SEARCH("Februari",E13)),"2026-02", IF(ISNUMBER(SEARCH("Maret",E13)),"2026-03", IF(ISNUMBER(SEARCH("April",E13)),"2026-04", IF(ISNUMBER(SEARCH("Mei",E13)),"2026-05", IF(ISNUMBER(SEARCH("Juni",E13)),"2026-06","")))))))))))) -> 2025-08 | E13: SPP Agustus | F13: 230000 | H13: =IF(ISNUMBER(SEARCH("Juli",E13)),230000,"") | I13: =DATE(LEFT(D13,4),RIGHT(D13,2),10) -> 45879
A14: T013 | B14: S002 | C14: spp | D14: =IF(ISNUMBER(SEARCH("Juli",E14)),"2025-07", IF(ISNUMBER(SEARCH("Agustus",E14)),"2025-08", IF(ISNUMBER(SEARCH("September",E14)),"2025-09", IF(ISNUMBER(SEARCH("Oktober",E14)),"2025-10", IF(ISNUMBER(SEARCH("November",E14)),"2025-11", IF(ISNUMBER(SEARCH("Desember",E14)),"2025-12", IF(ISNUMBER(SEARCH("Januari",E14)),"2026-01", IF(ISNUMBER(SEARCH("Februari",E14)),"2026-02", IF(ISNUMBER(SEARCH("Maret",E14)),"2026-03", IF(ISNUMBER(SEARCH("April",E14)),"2026-04", IF(ISNUMBER(SEARCH("Mei",E14)),"2026-05", IF(ISNUMBER(SEARCH("Juni",E14)),"2026-06","")))))))))))) -> 2025-09 | E14: SPP September | F14: 230000 | H14: =IF(ISNUMBER(SEARCH("Juli",E14)),230000,"") | I14: =DATE(LEFT(D14,4),RIGHT(D14,2),10) -> 45910
A15: T014 | B15: S002 | C15: spp | D15: =IF(ISNUMBER(SEARCH("Juli",E15)),"2025-07", IF(ISNUMBER(SEARCH("Agustus",E15)),"2025-08", IF(ISNUMBER(SEARCH("September",E15)),"2025-09", IF(ISNUMBER(SEARCH("Oktober",E15)),"2025-10", IF(ISNUMBER(SEARCH("November",E15)),"2025-11", IF(ISNUMBER(SEARCH("Desember",E15)),"2025-12", IF(ISNUMBER(SEARCH("Januari",E15)),"2026-01", IF(ISNUMBER(SEARCH("Februari",E15)),"2026-02", IF(ISNUMBER(SEARCH("Maret",E15)),"2026-03", IF(ISNUMBER(SEARCH("April",E15)),"2026-04", IF(ISNUMBER(SEARCH("Mei",E15)),"2026-05", IF(ISNUMBER(SEARCH("Juni",E15)),"2026-06","")))))))))))) -> 2025-10 | E15: SPP Oktober | F15: 230000 | H15: =IF(ISNUMBER(SEARCH("Juli",E15)),230000,"") | I15: =DATE(LEFT(D15,4),RIGHT(D15,2),10) -> 45940
A16: T015 | B16: S002 | C16: spp | D16: =IF(ISNUMBER(SEARCH("Juli",E16)),"2025-07", IF(ISNUMBER(SEARCH("Agustus",E16)),"2025-08", IF(ISNUMBER(SEARCH("September",E16)),"2025-09", IF(ISNUMBER(SEARCH("Oktober",E16)),"2025-10", IF(ISNUMBER(SEARCH("November",E16)),"2025-11", IF(ISNUMBER(SEARCH("Desember",E16)),"2025-12", IF(ISNUMBER(SEARCH("Januari",E16)),"2026-01", IF(ISNUMBER(SEARCH("Februari",E16)),"2026-02", IF(ISNUMBER(SEARCH("Maret",E16)),"2026-03", IF(ISNUMBER(SEARCH("April",E16)),"2026-04", IF(ISNUMBER(SEARCH("Mei",E16)),"2026-05", IF(ISNUMBER(SEARCH("Juni",E16)),"2026-06","")))))))))))) -> 2025-11 | E16: SPP November | F16: 230000 | H16: =IF(ISNUMBER(SEARCH("Juli",E16)),230000,"") | I16: =DATE(LEFT(D16,4),RIGHT(D16,2),10) -> 45971
A17: T016 | B17: S002 | C17: spp | D17: =IF(ISNUMBER(SEARCH("Juli",E17)),"2025-07", IF(ISNUMBER(SEARCH("Agustus",E17)),"2025-08", IF(ISNUMBER(SEARCH("September",E17)),"2025-09", IF(ISNUMBER(SEARCH("Oktober",E17)),"2025-10", IF(ISNUMBER(SEARCH("November",E17)),"2025-11", IF(ISNUMBER(SEARCH("Desember",E17)),"2025-12", IF(ISNUMBER(SEARCH("Januari",E17)),"2026-01", IF(ISNUMBER(SEARCH("Februari",E17)),"2026-02", IF(ISNUMBER(SEARCH("Maret",E17)),"2026-03", IF(ISNUMBER(SEARCH("April",E17)),"2026-04", IF(ISNUMBER(SEARCH("Mei",E17)),"2026-05", IF(ISNUMBER(SEARCH("Juni",E17)),"2026-06","")))))))))))) -> 2025-12 | E17: SPP Desember | F17: 230000 | H17: =IF(ISNUMBER(SEARCH("Juli",E17)),230000,"") | I17: =DATE(LEFT(D17,4),RIGHT(D17,2),10) -> 46001
A18: T017 | B18: S002 | C18: spp | D18: =IF(ISNUMBER(SEARCH("Juli",E18)),"2025-07", IF(ISNUMBER(SEARCH("Agustus",E18)),"2025-08", IF(ISNUMBER(SEARCH("September",E18)),"2025-09", IF(ISNUMBER(SEARCH("Oktober",E18)),"2025-10", IF(ISNUMBER(SEARCH("November",E18)),"2025-11", IF(ISNUMBER(SEARCH("Desember",E18)),"2025-12", IF(ISNUMBER(SEARCH("Januari",E18)),"2026-01", IF(ISNUMBER(SEARCH("Februari",E18)),"2026-02", IF(ISNUMBER(SEARCH("Maret",E18)),"2026-03", IF(ISNUMBER(SEARCH("April",E18)),"2026-04", IF(ISNUMBER(SEARCH("Mei",E18)),"2026-05", IF(ISNUMBER(SEARCH("Juni",E18)),"2026-06","")))))))))))) -> 2026-01 | E18: SPP Januari | F18: 230000 | H18: =IF(ISNUMBER(SEARCH("Juli",E18)),230000,"") | I18: =DATE(LEFT(D18,4),RIGHT(D18,2),10) -> 46032
A19: T018 | B19: S002 | C19: spp | D19: =IF(ISNUMBER(SEARCH("Juli",E19)),"2025-07", IF(ISNUMBER(SEARCH("Agustus",E19)),"2025-08", IF(ISNUMBER(SEARCH("September",E19)),"2025-09", IF(ISNUMBER(SEARCH("Oktober",E19)),"2025-10", IF(ISNUMBER(SEARCH("November",E19)),"2025-11", IF(ISNUMBER(SEARCH("Desember",E19)),"2025-12", IF(ISNUMBER(SEARCH("Januari",E19)),"2026-01", IF(ISNUMBER(SEARCH("Februari",E19)),"2026-02", IF(ISNUMBER(SEARCH("Maret",E19)),"2026-03", IF(ISNUMBER(SEARCH("April",E19)),"2026-04", IF(ISNUMBER(SEARCH("Mei",E19)),"2026-05", IF(ISNUMBER(SEARCH("Juni",E19)),"2026-06","")))))))))))) -> 2026-02 | E19: SPP Februari | F19: 230000 | H19: =IF(ISNUMBER(SEARCH("Juli",E19)),230000,"") | I19: =DATE(LEFT(D19,4),RIGHT(D19,2),10) -> 46063
A20: T019 | B20: S002 | C20: spp | D20: =IF(ISNUMBER(SEARCH("Juli",E20)),"2025-07", IF(ISNUMBER(SEARCH("Agustus",E20)),"2025-08", IF(ISNUMBER(SEARCH("September",E20)),"2025-09", IF(ISNUMBER(SEARCH("Oktober",E20)),"2025-10", IF(ISNUMBER(SEARCH("November",E20)),"2025-11", IF(ISNUMBER(SEARCH("Desember",E20)),"2025-12", IF(ISNUMBER(SEARCH("Januari",E20)),"2026-01", IF(ISNUMBER(SEARCH("Februari",E20)),"2026-02", IF(ISNUMBER(SEARCH("Maret",E20)),"2026-03", IF(ISNUMBER(SEARCH("April",E20)),"2026-04", IF(ISNUMBER(SEARCH("Mei",E20)),"2026-05", IF(ISNUMBER(SEARCH("Juni",E20)),"2026-06","")))))))))))) -> 2026-03 | E20: SPP Maret | F20: 230000 | H20: =IF(ISNUMBER(SEARCH("Juli",E20)),230000,"") | I20: =DATE(LEFT(D20,4),RIGHT(D20,2),10) -> 46091
A21: T020 | B21: S002 | C21: spp | D21: =IF(ISNUMBER(SEARCH("Juli",E21)),"2025-07", IF(ISNUMBER(SEARCH("Agustus",E21)),"2025-08", IF(ISNUMBER(SEARCH("September",E21)),"2025-09", IF(ISNUMBER(SEARCH("Oktober",E21)),"2025-10", IF(ISNUMBER(SEARCH("November",E21)),"2025-11", IF(ISNUMBER(SEARCH("Desember",E21)),"2025-12", IF(ISNUMBER(SEARCH("Januari",E21)),"2026-01", IF(ISNUMBER(SEARCH("Februari",E21)),"2026-02", IF(ISNUMBER(SEARCH("Maret",E21)),"2026-03", IF(ISNUMBER(SEARCH("April",E21)),"2026-04", IF(ISNUMBER(SEARCH("Mei",E21)),"2026-05", IF(ISNUMBER(SEARCH("Juni",E21)),"2026-06","")))))))))))) -> 2026-04 | E21: SPP April | F21: 230000 | H21: =IF(ISNUMBER(SEARCH("Juli",E21)),230000,"") | I21: =DATE(LEFT(D21,4),RIGHT(D21,2),10) -> 46122
A22: T021 | B22: S003 | C22: spp | D22: =IF(ISNUMBER(SEARCH("Juli",E22)),"2025-07", IF(ISNUMBER(SEARCH("Agustus",E22)),"2025-08", IF(ISNUMBER(SEARCH("September",E22)),"2025-09", IF(ISNUMBER(SEARCH("Oktober",E22)),"2025-10", IF(ISNUMBER(SEARCH("November",E22)),"2025-11", IF(ISNUMBER(SEARCH("Desember",E22)),"2025-12", IF(ISNUMBER(SEARCH("Januari",E22)),"2026-01", IF(ISNUMBER(SEARCH("Februari",E22)),"2026-02", IF(ISNUMBER(SEARCH("Maret",E22)),"2026-03", IF(ISNUMBER(SEARCH("April",E22)),"2026-04", IF(ISNUMBER(SEARCH("Mei",E22)),"2026-05", IF(ISNUMBER(SEARCH("Juni",E22)),"2026-06","")))))))))))) -> 2025-07 | E22: SPP Juli | F22: 230000 | G22: pendaftaran | H22: =IF(ISNUMBER(SEARCH("Juli",E22)),230000,"") -> 230000 | I22: =DATE(LEFT(D22,4),RIGHT(D22,2),10) -> 45848
A23: T022 | B23: S003 | C23: spp | D23: =IF(ISNUMBER(SEARCH("Juli",E23)),"2025-07", IF(ISNUMBER(SEARCH("Agustus",E23)),"2025-08", IF(ISNUMBER(SEARCH("September",E23)),"2025-09", IF(ISNUMBER(SEARCH("Oktober",E23)),"2025-10", IF(ISNUMBER(SEARCH("November",E23)),"2025-11", IF(ISNUMBER(SEARCH("Desember",E23)),"2025-12", IF(ISNUMBER(SEARCH("Januari",E23)),"2026-01", IF(ISNUMBER(SEARCH("Februari",E23)),"2026-02", IF(ISNUMBER(SEARCH("Maret",E23)),"2026-03", IF(ISNUMBER(SEARCH("April",E23)),"2026-04", IF(ISNUMBER(SEARCH("Mei",E23)),"2026-05", IF(ISNUMBER(SEARCH("Juni",E23)),"2026-06","")))))))))))) -> 2025-08 | E23: SPP Agustus | F23: 230000 | H23: =IF(ISNUMBER(SEARCH("Juli",E23)),230000,"") | I23: =DATE(LEFT(D23,4),RIGHT(D23,2),10) -> 45879
A24: T023 | B24: S003 | C24: spp | D24: =IF(ISNUMBER(SEARCH("Juli",E24)),"2025-07", IF(ISNUMBER(SEARCH("Agustus",E24)),"2025-08", IF(ISNUMBER(SEARCH("September",E24)),"2025-09", IF(ISNUMBER(SEARCH("Oktober",E24)),"2025-10", IF(ISNUMBER(SEARCH("November",E24)),"2025-11", IF(ISNUMBER(SEARCH("Desember",E24)),"2025-12", IF(ISNUMBER(SEARCH("Januari",E24)),"2026-01", IF(ISNUMBER(SEARCH("Februari",E24)),"2026-02", IF(ISNUMBER(SEARCH("Maret",E24)),"2026-03", IF(ISNUMBER(SEARCH("April",E24)),"2026-04", IF(ISNUMBER(SEARCH("Mei",E24)),"2026-05", IF(ISNUMBER(SEARCH("Juni",E24)),"2026-06","")))))))))))) -> 2025-09 | E24: SPP September | F24: 230000 | H24: =IF(ISNUMBER(SEARCH("Juli",E24)),230000,"") | I24: =DATE(LEFT(D24,4),RIGHT(D24,2),10) -> 45910
A25: T024 | B25: S003 | C25: spp | D25: =IF(ISNUMBER(SEARCH("Juli",E25)),"2025-07", IF(ISNUMBER(SEARCH("Agustus",E25)),"2025-08", IF(ISNUMBER(SEARCH("September",E25)),"2025-09", IF(ISNUMBER(SEARCH("Oktober",E25)),"2025-10", IF(ISNUMBER(SEARCH("November",E25)),"2025-11", IF(ISNUMBER(SEARCH("Desember",E25)),"2025-12", IF(ISNUMBER(SEARCH("Januari",E25)),"2026-01", IF(ISNUMBER(SEARCH("Februari",E25)),"2026-02", IF(ISNUMBER(SEARCH("Maret",E25)),"2026-03", IF(ISNUMBER(SEARCH("April",E25)),"2026-04", IF(ISNUMBER(SEARCH("Mei",E25)),"2026-05", IF(ISNUMBER(SEARCH("Juni",E25)),"2026-06","")))))))))))) -> 2025-10 | E25: SPP Oktober | F25: 230000 | H25: =IF(ISNUMBER(SEARCH("Juli",E25)),230000,"") | I25: =DATE(LEFT(D25,4),RIGHT(D25,2),10) -> 45940
A26: T025 | B26: S003 | C26: spp | D26: =IF(ISNUMBER(SEARCH("Juli",E26)),"2025-07", IF(ISNUMBER(SEARCH("Agustus",E26)),"2025-08", IF(ISNUMBER(SEARCH("September",E26)),"2025-09", IF(ISNUMBER(SEARCH("Oktober",E26)),"2025-10", IF(ISNUMBER(SEARCH("November",E26)),"2025-11", IF(ISNUMBER(SEARCH("Desember",E26)),"2025-12", IF(ISNUMBER(SEARCH("Januari",E26)),"2026-01", IF(ISNUMBER(SEARCH("Februari",E26)),"2026-02", IF(ISNUMBER(SEARCH("Maret",E26)),"2026-03", IF(ISNUMBER(SEARCH("April",E26)),"2026-04", IF(ISNUMBER(SEARCH("Mei",E26)),"2026-05", IF(ISNUMBER(SEARCH("Juni",E26)),"2026-06","")))))))))))) -> 2025-11 | E26: SPP November | F26: 230000 | H26: =IF(ISNUMBER(SEARCH("Juli",E26)),230000,"") | I26: =DATE(LEFT(D26,4),RIGHT(D26,2),10) -> 45971
A27: T026 | B27: S003 | C27: spp | D27: =IF(ISNUMBER(SEARCH("Juli",E27)),"2025-07", IF(ISNUMBER(SEARCH("Agustus",E27)),"2025-08", IF(ISNUMBER(SEARCH("September",E27)),"2025-09", IF(ISNUMBER(SEARCH("Oktober",E27)),"2025-10", IF(ISNUMBER(SEARCH("November",E27)),"2025-11", IF(ISNUMBER(SEARCH("Desember",E27)),"2025-12", IF(ISNUMBER(SEARCH("Januari",E27)),"2026-01", IF(ISNUMBER(SEARCH("Februari",E27)),"2026-02", IF(ISNUMBER(SEARCH("Maret",E27)),"2026-03", IF(ISNUMBER(SEARCH("April",E27)),"2026-04", IF(ISNUMBER(SEARCH("Mei",E27)),"2026-05", IF(ISNUMBER(SEARCH("Juni",E27)),"2026-06","")))))))))))) -> 2025-12 | E27: SPP Desember | F27: 230000 | H27: =IF(ISNUMBER(SEARCH("Juli",E27)),230000,"") | I27: =DATE(LEFT(D27,4),RIGHT(D27,2),10) -> 46001
A28: T027 | B28: S003 | C28: spp | D28: =IF(ISNUMBER(SEARCH("Juli",E28)),"2025-07", IF(ISNUMBER(SEARCH("Agustus",E28)),"2025-08", IF(ISNUMBER(SEARCH("September",E28)),"2025-09", IF(ISNUMBER(SEARCH("Oktober",E28)),"2025-10", IF(ISNUMBER(SEARCH("November",E28)),"2025-11", IF(ISNUMBER(SEARCH("Desember",E28)),"2025-12", IF(ISNUMBER(SEARCH("Januari",E28)),"2026-01", IF(ISNUMBER(SEARCH("Februari",E28)),"2026-02", IF(ISNUMBER(SEARCH("Maret",E28)),"2026-03", IF(ISNUMBER(SEARCH("April",E28)),"2026-04", IF(ISNUMBER(SEARCH("Mei",E28)),"2026-05", IF(ISNUMBER(SEARCH("Juni",E28)),"2026-06","")))))))))))) -> 2026-01 | E28: SPP Januari | F28: 230000 | H28: =IF(ISNUMBER(SEARCH("Juli",E28)),230000,"") | I28: =DATE(LEFT(D28,4),RIGHT(D28,2),10) -> 46032
A29: T028 | B29: S003 | C29: spp | D29: =IF(ISNUMBER(SEARCH("Juli",E29)),"2025-07", IF(ISNUMBER(SEARCH("Agustus",E29)),"2025-08", IF(ISNUMBER(SEARCH("September",E29)),"2025-09", IF(ISNUMBER(SEARCH("Oktober",E29)),"2025-10", IF(ISNUMBER(SEARCH("November",E29)),"2025-11", IF(ISNUMBER(SEARCH("Desember",E29)),"2025-12", IF(ISNUMBER(SEARCH("Januari",E29)),"2026-01", IF(ISNUMBER(SEARCH("Februari",E29)),"2026-02", IF(ISNUMBER(SEARCH("Maret",E29)),"2026-03", IF(ISNUMBER(SEARCH("April",E29)),"2026-04", IF(ISNUMBER(SEARCH("Mei",E29)),"2026-05", IF(ISNUMBER(SEARCH("Juni",E29)),"2026-06","")))))))))))) -> 2026-02 | E29: SPP Februari | F29: 230000 | H29: =IF(ISNUMBER(SEARCH("Juli",E29)),230000,"") | I29: =DATE(LEFT(D29,4),RIGHT(D29,2),10) -> 46063
A30: T029 | B30: S003 | C30: spp | D30: =IF(ISNUMBER(SEARCH("Juli",E30)),"2025-07", IF(ISNUMBER(SEARCH("Agustus",E30)),"2025-08", IF(ISNUMBER(SEARCH("September",E30)),"2025-09", IF(ISNUMBER(SEARCH("Oktober",E30)),"2025-10", IF(ISNUMBER(SEARCH("November",E30)),"2025-11", IF(ISNUMBER(SEARCH("Desember",E30)),"2025-12", IF(ISNUMBER(SEARCH("Januari",E30)),"2026-01", IF(ISNUMBER(SEARCH("Februari",E30)),"2026-02", IF(ISNUMBER(SEARCH("Maret",E30)),"2026-03", IF(ISNUMBER(SEARCH("April",E30)),"2026-04", IF(ISNUMBER(SEARCH("Mei",E30)),"2026-05", IF(ISNUMBER(SEARCH("Juni",E30)),"2026-06","")))))))))))) -> 2026-03 | E30: SPP Maret | F30: 230000 | H30: =IF(ISNUMBER(SEARCH("Juli",E30)),230000,"") | I30: =DATE(LEFT(D30,4),RIGHT(D30,2),10) -> 46091
A31: T030 | B31: S003 | C31: spp | D31: =IF(ISNUMBER(SEARCH("Juli",E31)),"2025-07", IF(ISNUMBER(SEARCH("Agustus",E31)),"2025-08", IF(ISNUMBER(SEARCH("September",E31)),"2025-09", IF(ISNUMBER(SEARCH("Oktober",E31)),"2025-10", IF(ISNUMBER(SEARCH("November",E31)),"2025-11", IF(ISNUMBER(SEARCH("Desember",E31)),"2025-12", IF(ISNUMBER(SEARCH("Januari",E31)),"2026-01", IF(ISNUMBER(SEARCH("Februari",E31)),"2026-02", IF(ISNUMBER(SEARCH("Maret",E31)),"2026-03", IF(ISNUMBER(SEARCH("April",E31)),"2026-04", IF(ISNUMBER(SEARCH("Mei",E31)),"2026-05", IF(ISNUMBER(SEARCH("Juni",E31)),"2026-06","")))))))))))) -> 2026-04 | E31: SPP April | F31: 230000 | H31: =IF(ISNUMBER(SEARCH("Juli",E31)),230000,"") | I31: =DATE(LEFT(D31,4),RIGHT(D31,2),10) -> 46122
A32: T031 | B32: S004 | C32: spp | D32: =IF(ISNUMBER(SEARCH("Juli",E32)),"2025-07", IF(ISNUMBER(SEARCH("Agustus",E32)),"2025-08", IF(ISNUMBER(SEARCH("September",E32)),"2025-09", IF(ISNUMBER(SEARCH("Oktober",E32)),"2025-10", IF(ISNUMBER(SEARCH("November",E32)),"2025-11", IF(ISNUMBER(SEARCH("Desember",E32)),"2025-12", IF(ISNUMBER(SEARCH("Januari",E32)),"2026-01", IF(ISNUMBER(SEARCH("Februari",E32)),"2026-02", IF(ISNUMBER(SEARCH("Maret",E32)),"2026-03", IF(ISNUMBER(SEARCH("April",E32)),"2026-04", IF(ISNUMBER(SEARCH("Mei",E32)),"2026-05", IF(ISNUMBER(SEARCH("Juni",E32)),"2026-06","")))))))))))) -> 2025-07 | E32: SPP Juli | F32: 230000 | G32: pendaftaran | H32: =IF(ISNUMBER(SEARCH("Juli",E32)),230000,"") -> 230000 | I32: =DATE(LEFT(D32,4),RIGHT(D32,2),10) -> 45848
A33: T032 | B33: S004 | C33: spp | D33: =IF(ISNUMBER(SEARCH("Juli",E33)),"2025-07", IF(ISNUMBER(SEARCH("Agustus",E33)),"2025-08", IF(ISNUMBER(SEARCH("September",E33)),"2025-09", IF(ISNUMBER(SEARCH("Oktober",E33)),"2025-10", IF(ISNUMBER(SEARCH("November",E33)),"2025-11", IF(ISNUMBER(SEARCH("Desember",E33)),"2025-12", IF(ISNUMBER(SEARCH("Januari",E33)),"2026-01", IF(ISNUMBER(SEARCH("Februari",E33)),"2026-02", IF(ISNUMBER(SEARCH("Maret",E33)),"2026-03", IF(ISNUMBER(SEARCH("April",E33)),"2026-04", IF(ISNUMBER(SEARCH("Mei",E33)),"2026-05", IF(ISNUMBER(SEARCH("Juni",E33)),"2026-06","")))))))))))) -> 2025-08 | E33: SPP Agustus | F33: 230000 | H33: =IF(ISNUMBER(SEARCH("Juli",E33)),230000,"") | I33: =DATE(LEFT(D33,4),RIGHT(D33,2),10) -> 45879
A34: T033 | B34: S004 | C34: spp | D34: =IF(ISNUMBER(SEARCH("Juli",E34)),"2025-07", IF(ISNUMBER(SEARCH("Agustus",E34)),"2025-08", IF(ISNUMBER(SEARCH("September",E34)),"2025-09", IF(ISNUMBER(SEARCH("Oktober",E34)),"2025-10", IF(ISNUMBER(SEARCH("November",E34)),"2025-11", IF(ISNUMBER(SEARCH("Desember",E34)),"2025-12", IF(ISNUMBER(SEARCH("Januari",E34)),"2026-01", IF(ISNUMBER(SEARCH("Februari",E34)),"2026-02", IF(ISNUMBER(SEARCH("Maret",E34)),"2026-03", IF(ISNUMBER(SEARCH("April",E34)),"2026-04", IF(ISNUMBER(SEARCH("Mei",E34)),"2026-05", IF(ISNUMBER(SEARCH("Juni",E34)),"2026-06","")))))))))))) -> 2025-09 | E34: SPP September | F34: 230000 | H34: =IF(ISNUMBER(SEARCH("Juli",E34)),230000,"") | I34: =DATE(LEFT(D34,4),RIGHT(D34,2),10) -> 45910
A35: T034 | B35: S004 | C35: spp | D35: =IF(ISNUMBER(SEARCH("Juli",E35)),"2025-07", IF(ISNUMBER(SEARCH("Agustus",E35)),"2025-08", IF(ISNUMBER(SEARCH("September",E35)),"2025-09", IF(ISNUMBER(SEARCH("Oktober",E35)),"2025-10", IF(ISNUMBER(SEARCH("November",E35)),"2025-11", IF(ISNUMBER(SEARCH("Desember",E35)),"2025-12", IF(ISNUMBER(SEARCH("Januari",E35)),"2026-01", IF(ISNUMBER(SEARCH("Februari",E35)),"2026-02", IF(ISNUMBER(SEARCH("Maret",E35)),"2026-03", IF(ISNUMBER(SEARCH("April",E35)),"2026-04", IF(ISNUMBER(SEARCH("Mei",E35)),"2026-05", IF(ISNUMBER(SEARCH("Juni",E35)),"2026-06","")))))))))))) -> 2025-10 | E35: SPP Oktober | F35: 230000 | H35: =IF(ISNUMBER(SEARCH("Juli",E35)),230000,"") | I35: =DATE(LEFT(D35,4),RIGHT(D35,2),10) -> 45940
A36: T035 | B36: S004 | C36: spp | D36: =IF(ISNUMBER(SEARCH("Juli",E36)),"2025-07", IF(ISNUMBER(SEARCH("Agustus",E36)),"2025-08", IF(ISNUMBER(SEARCH("September",E36)),"2025-09", IF(ISNUMBER(SEARCH("Oktober",E36)),"2025-10", IF(ISNUMBER(SEARCH("November",E36)),"2025-11", IF(ISNUMBER(SEARCH("Desember",E36)),"2025-12", IF(ISNUMBER(SEARCH("Januari",E36)),"2026-01", IF(ISNUMBER(SEARCH("Februari",E36)),"2026-02", IF(ISNUMBER(SEARCH("Maret",E36)),"2026-03", IF(ISNUMBER(SEARCH("April",E36)),"2026-04", IF(ISNUMBER(SEARCH("Mei",E36)),"2026-05", IF(ISNUMBER(SEARCH("Juni",E36)),"2026-06","")))))))))))) -> 2025-11 | E36: SPP November | F36: 230000 | H36: =IF(ISNUMBER(SEARCH("Juli",E36)),230000,"") | I36: =DATE(LEFT(D36,4),RIGHT(D36,2),10) -> 45971
A37: T036 | B37: S004 | C37: spp | D37: =IF(ISNUMBER(SEARCH("Juli",E37)),"2025-07", IF(ISNUMBER(SEARCH("Agustus",E37)),"2025-08", IF(ISNUMBER(SEARCH("September",E37)),"2025-09", IF(ISNUMBER(SEARCH("Oktober",E37)),"2025-10", IF(ISNUMBER(SEARCH("November",E37)),"2025-11", IF(ISNUMBER(SEARCH("Desember",E37)),"2025-12", IF(ISNUMBER(SEARCH("Januari",E37)),"2026-01", IF(ISNUMBER(SEARCH("Februari",E37)),"2026-02", IF(ISNUMBER(SEARCH("Maret",E37)),"2026-03", IF(ISNUMBER(SEARCH("April",E37)),"2026-04", IF(ISNUMBER(SEARCH("Mei",E37)),"2026-05", IF(ISNUMBER(SEARCH("Juni",E37)),"2026-06","")))))))))))) -> 2025-12 | E37: SPP Desember | F37: 230000 | H37: =IF(ISNUMBER(SEARCH("Juli",E37)),230000,"") | I37: =DATE(LEFT(D37,4),RIGHT(D37,2),10) -> 46001
A38: T037 | B38: S004 | C38: spp | D38: =IF(ISNUMBER(SEARCH("Juli",E38)),"2025-07", IF(ISNUMBER(SEARCH("Agustus",E38)),"2025-08", IF(ISNUMBER(SEARCH("September",E38)),"2025-09", IF(ISNUMBER(SEARCH("Oktober",E38)),"2025-10", IF(ISNUMBER(SEARCH("November",E38)),"2025-11", IF(ISNUMBER(SEARCH("Desember",E38)),"2025-12", IF(ISNUMBER(SEARCH("Januari",E38)),"2026-01", IF(ISNUMBER(SEARCH("Februari",E38)),"2026-02", IF(ISNUMBER(SEARCH("Maret",E38)),"2026-03", IF(ISNUMBER(SEARCH("April",E38)),"2026-04", IF(ISNUMBER(SEARCH("Mei",E38)),"2026-05", IF(ISNUMBER(SEARCH("Juni",E38)),"2026-06","")))))))))))) -> 2026-01 | E38: SPP Januari | F38: 230000 | H38: =IF(ISNUMBER(SEARCH("Juli",E38)),230000,"") | I38: =DATE(LEFT(D38,4),RIGHT(D38,2),10) -> 46032
A39: T038 | B39: S004 | C39: spp | D39: =IF(ISNUMBER(SEARCH("Juli",E39)),"2025-07", IF(ISNUMBER(SEARCH("Agustus",E39)),"2025-08", IF(ISNUMBER(SEARCH("September",E39)),"2025-09", IF(ISNUMBER(SEARCH("Oktober",E39)),"2025-10", IF(ISNUMBER(SEARCH("November",E39)),"2025-11", IF(ISNUMBER(SEARCH("Desember",E39)),"2025-12", IF(ISNUMBER(SEARCH("Januari",E39)),"2026-01", IF(ISNUMBER(SEARCH("Februari",E39)),"2026-02", IF(ISNUMBER(SEARCH("Maret",E39)),"2026-03", IF(ISNUMBER(SEARCH("April",E39)),"2026-04", IF(ISNUMBER(SEARCH("Mei",E39)),"2026-05", IF(ISNUMBER(SEARCH("Juni",E39)),"2026-06","")))))))))))) -> 2026-02 | E39: SPP Februari | F39: 230000 | H39: =IF(ISNUMBER(SEARCH("Juli",E39)),230000,"") | I39: =DATE(LEFT(D39,4),RIGHT(D39,2),10) -> 46063
A40: T039 | B40: S004 | C40: spp | D40: =IF(ISNUMBER(SEARCH("Juli",E40)),"2025-07", IF(ISNUMBER(SEARCH("Agustus",E40)),"2025-08", IF(ISNUMBER(SEARCH("September",E40)),"2025-09", IF(ISNUMBER(SEARCH("Oktober",E40)),"2025-10", IF(ISNUMBER(SEARCH("November",E40)),"2025-11", IF(ISNUMBER(SEARCH("Desember",E40)),"2025-12", IF(ISNUMBER(SEARCH("Januari",E40)),"2026-01", IF(ISNUMBER(SEARCH("Februari",E40)),"2026-02", IF(ISNUMBER(SEARCH("Maret",E40)),"2026-03", IF(ISNUMBER(SEARCH("April",E40)),"2026-04", IF(ISNUMBER(SEARCH("Mei",E40)),"2026-05", IF(ISNUMBER(SEARCH("Juni",E40)),"2026-06","")))))))))))) -> 2026-03 | E40: SPP Maret | F40: 230000 | H40: =IF(ISNUMBER(SEARCH("Juli",E40)),230000,"") | I40: =DATE(LEFT(D40,4),RIGHT(D40,2),10) -> 46091
...

Sheet pembayaran
C1: kode_import_pembayaran | D1: kode_import_tagihan | E1: tanggal_pembayaran | F1: jumlah | G1: metode_pembayaran | H1: catatan
A2: Abhimanyu Kenzo Novendra | B2: S001 | C2: P002 | D2: T002 | E2: 45874 | F2: 230000 | G2: Tunai
A3: Abhimanyu Kenzo Novendra | B3: S001 | C3: P003 | D3: T003 | E3: 45915 | F3: 230000 | G3: Tunai
A4: Abhimanyu Kenzo Novendra | B4: S001 | C4: P004 | D4: T004 | E4: 45936 | F4: 230000 | G4: Tunai
A5: Abhimanyu Kenzo Novendra | B5: S001 | C5: P005 | D5: T005 | E5: 45967 | F5: 230000 | G5: Tunai
A6: Abhimanyu Kenzo Novendra | B6: S001 | C6: P006 | D6: T006 | E6: 46008 | F6: 230000 | G6: Tabungan
A7: Abhimanyu Kenzo Novendra | B7: S001 | C7: P007 | D7: T007 | E7: 46044 | F7: 230000 | G7: Tabungan
A8: Abhimanyu Kenzo Novendra | B8: S001 | C8: P008 | D8: T008 | E8: 46065 | F8: 230000 | G8: Tabungan
A9: Abhimanyu Kenzo Novendra | B9: S001 | C9: P009 | D9: T009 | E9: 46092 | F9: 230000 | G9: Tunai
A10: Abhimanyu Kenzo Novendra | B10: S001 | C10: P010 | D10: T010 | E10: 46120 | F10: 230000 | G10: Tunai
A11: Adzriel Al Mahdi | B11: S002 | C11: P012 | D11: T012 | E11: 45866 | F11: 230000 | G11: Tunai
A12: Adzriel Al Mahdi | B12: S002 | C12: P013 | D12: T013 | E12: 45897 | F12: 230000 | G12: Tunai
A13: Adzriel Al Mahdi | B13: S002 | C13: P014 | D13: T014 | E13: 45933 | F13: 230000 | G13: Tunai
... A74: Fawwaz Khayri Zain | B74: S011 | C74: P080 | D74: T081 | E74: 46091 | F74: 230000 | G74: Tunai
A75: Gita Nuraisya Gunawan | B75: S012 | C75: P081 | D75: T082 | E75: 31/4/2026 | F75: 230000 | G75: Tunai
A76: Fawwaz Khayri Zain | B76: S011 | C76: P093 | D76: T094 | E76: 220000 | F76: 220000 | G76: Tunai
A77: Fawwaz Khayri Zain | B77: S011 | C77: P094 | D77: T095 | E77: 220000 | F77: 220000 | G77: Tunai
A78: Fawwaz Khayri Zain | B78: S011 | C78: P095 | D78: T096 | E78: 220000 | F78: 220000 | G78: Tunai
A79: Fawwaz Khayri Zain | B79: S011 | C79: P096 | D79: T097 | E79: 220000 | F79: 220000 | G79: Tunai
A80: Fawwaz Khayri Zain | B80: S011 | C80: P097 | D80: T098 | E80: 220000 | F80: 220000 | G80: Tunai
A81: Fawwaz Khayri Zain | B81: S011 | C81: P098 | D81: T099 | E81: 220000 | F81: 220000 | G81: Tunai
A82: Fawwaz Khayri Zain | B82: S011 | C82: P099 | D82: T100 | E82: 220000 | F82: 220000 | G82: Tunai
A83: Fawwaz Khayri Zain | B83: S011 | C83: P100 | D83: T101 | E83: 220000 | F83: 220000 | G83: Tunai
A84: Fawwaz Khayri Zain | B84: S011 | C84: P101 | D84: T102 | E84: 220000 | F84: 220000 | G84: Tunai
A85: Gita Nuraisya Gunawan | B85: S012 | C85: P103 | D85: T104 | E85: 45873 | F85: 230000 | G85: Tunai
A86: Gita Nuraisya Gunawan | B86: S012 | C86: P104 | D86: T105 | E86: 45902 | F86: 230000 | G86: Tunai
A87: Gita Nuraisya Gunawan | B87: S012 | C87: P105 | D87: T106 | E87: 45951 | F87: 230000 | G87: Tunai
... A300: Raja Azki Setyawan | B300: S038 | C300: P343 | D300: T344 | E300: 46123 | F300: 230000 | G300: Tunai
A301: Gita Nuraisya Gunawan | C301: P344 | D301: T345 | E301: 46118 | F301: 155000 | G301: Tabungan
A302: Elma Hazel Maulida | C302: P345 | D302: T346 | E302: 46118 | F302: 155000 | G302: Tunai
A303: Aqmar Nadhif Ramdhan | C303: P346 | D303: T347 | E303: 46118 | F303: 155000 | G303: Tunai
A304: Keanu Osama Al Jabbar | C304: P347 | D304: T348 | E304: 46119 | F304: 155000 | G304: Transfer
A305: Adzriel Al Mahdi | C305: P348 | D305: T349 | E305: 46120 | F305: 155000 | G305: Tunai
A306: fariz | C306: P349 | D306: T350 | E306: 46120 | F306: 155000 | G306: Tunai
A307: al | C307: P350 | D307: T351 | E307: 46120 | F307: 155000 | G307: Transfer
A308: Raissa Salsabila Aisy | C308: P351 | D308: T352 | E308: 46121 | F308: 155000 | G308: Tunai
A309: Fawwaz Khayri Zain | C309: P352 | D309: T353 | E309: 46121 | F309: 155000 | G309: Tunai
A310: M. Dhaffin Al Haqqi | C310: P353 | D310: T354 | E310: 46121 | F310: 155000 | G310: Tunai
A311: Afifa Aina Herita | C311: P354 | D311: T355 | E311: 46122 | F311: 155000 | G311: Tunai
A312: Naufal Al Fauzan | C312: P355 | D312: T356 | E312: 46122 | F312: 155000 | G312: Transfer
...

Sheet referensi
A1: status | B1: jenis_masuk | C1: alasan_keluar | D1: jenis_tagihan_aktif | E1: metode_pembayaran_aktif | F1: promo_aktif | G1: kelas_aktif
A2: aktif/keluar | B2: awal_tahun/pindahan | C2: pindah_sekolah/berhenti_lainnya | D2: SPP, Pendaftaran, Daftar Ulang, Kegiatan, Administrasi, Lainnya | E2: Tunai, Transfer, Tabungan | F2: Tidak ada | G2: Kelompok Bermain/Mawar, TK B/Melati, TK A/Anggrek
